Workbook
Name Slicer_Month: #N/A
Name Slicer_Vendor_Name1: #N/A

Sheet Detail1
A1: Details for Sum of OTD in Values - Vendor Name: Omega Industries
A3: PO Number | B3: Vendor ID | C3: Vendor Name | D3: Category | E3: Month | F3: Order Qty | G3: Received Qty | H3: Planned Date | I3: Actual Receipt Date | J3: Defect Qty | K3: Unit Price | L3: Delivery Delay | M3: OTD | N3: Fill Rate | O3: Quality Rate | P3: Order Value | Q3: Cost Score | R3: OTD in Values | S3: Vendor Score
A4: PO1001 | B4: V006 | C4: Omega Industries | D4: IC | E4: Dec | F4: 3249 | G4: 3071 | H4: 46383 | I4: 46392 | J4: 369 | K4: 151 | L4: 9 | M4: 0 | N4: 0.94521391 | O4: 0.8798437 | P4: 463721 | Q4: 0.033112583 | R4: 1 | S4: 0.45630715
A5: PO1498 | B5: V006 | C5: Omega Industries | D5: PCB | E5: Feb | F5: 3448 | G5: 3431 | H5: 46070 | I5: 46068 | J5: 416 | K5: 28 | L5: -2 | M5: 1 | N5: 0.99506961 | O5: 0.87875255 | P5: 96068 | Q5: 0.17857143 | R5: 0 | S5: 0.88049683
A6: PO1470 | B6: V006 | C6: Omega Industries | D6: PCB | E6: May | F6: 2364 | G6: 2179 | H6: 46155 | I6: 46164 | J6: 266 | K6: 63 | L6: 9 | M6: 0 | N6: 0.92174281 | O6: 0.87792565 | P6: 137277 | Q6: 0.079365079 | R6: 1 | S6: 0.45566277
A7: PO1467 | B7: V006 | C7: Omega Industries | D7: Connector | E7: Jun | F7: 4814 | G7: 4713 | H7: 46199 | I7: 46197 | J7: 570 | K7: 81 | L7: -2 | M7: 1 | N7: 0.97901953 | O7: 0.87905792 | P7: 381753 | Q7: 0.061728395 | R7: 0 | S7: 0.86569412
A8: PO1463 | B8: V006 | C8: Omega Industries | D8: Capacitor | E8: Jan | F8: 2032 | G8: 1873 | H8: 46035 | I8: 46036 | J8: 226 | K8: 141 | L8: 1 | M8: 0 | N8: 0.92175197 | O8: 0.87933796 | P8: 264093 | Q8: 0.035460993 | R8: 1 | S8: 0.45169788
A9: PO1459 | B9: V006 | C9: Omega Industries | D9: IC | E9: Dec | F9: 3857 | G9: 3769 | H9: 46370 | I9: 46373 | J9: 457 | K9: 168 | L9: 3 | M9: 0 | N9: 0.97718434 | O9: 0.87874768 | P9: 633192 | Q9: 0.029761905 | R9: 1 | S9: 0.46203736
A10: PO1449 | B10: V006 | C10: Omega Industries | D10: IC | E10: Mar | F10: 3346 | G10: 3121 | H10: 46107 | I10: 46114 | J10: 376 | K10: 142 | L10: 7 | M10: 0 | N10: 0.93275553 | O10: 0.87952579 | P10: 443182 | Q10: 0.035211268 | R10: 1 | S10: 0.45392997
A11: PO1444 | B11: V006 | C11: Omega Industries | D11: PCB | E11: Oct | F11: 648 | G11: 648 | H11: 46319 | I11: 46329 | J11: 78 | K11: 140 | L11: 10 | M11: 0 | N11: 1 | O11: 0.87962963 | P11: 90720 | Q11: 0.035714286 | R11: 1 | S11: 0.46746032
A12: PO1429 | B12: V006 | C12: Omega Industries | D12: PCB | E12: Jun | F12: 4927 | G12: 4763 | H12: 46184 | I12: 46184 | J12: 572 | K12: 230 | L12: 0 | M12: 1 | N12: 0.96671402 | O12: 0.87990762 | P12: 1095490 | Q12: 0.02173913 | R12: 0 | S12: 0.859489
A13: PO1427 | B13: V006 | C13: Omega Industries | D13: Connector | E13: Feb | F13: 3409 | G13: 3312 | H13: 46056 | I13: 46054 | J13: 401 | K13: 46 | L13: -2 | M13: 1 | N13: 0.97154591 | O13: 0.87892512 | P13: 152352 | Q13: 0.10869565 | R13: 0 | S13: 0.86885628
A14: PO1417 | B14: V006 | C14: Omega Industries | D14: PCB | E14: May | F14: 1193 | G14: 1130 | H14: 46145 | I14: 46145 | J14: 140 | K14: 71 | L14: 0 | M14: 1 | N14: 0.94719195 | O14: 0.87610619 | P14: 80230 | Q14: 0.070422535 | R14: 0 | S14: 0.8593125
A15: PO1404 | B15: V006 | C15: Omega Industries | D15: Capacitor | E15: Mar | F15: 1163 | G15: 1097 | H15: 46095 | I15: 46095 | J15: 137 | K15: 149 | L15: 0 | M15: 1 | N15: 0.94325021 | O15: 0.87511395 | P15: 163453 | Q15: 0.033557047 | R15: 0 | S15: 0.85453993
... A51: PO1066 | B51: V006 | C51: Omega Industries | D51: PCB | E51: Sep | F51: 3304 | G51: 3078 | H51: 46278 | I51: 46276 | J51: 374 | K51: 85 | L51: -2 | M51: 1 | N51: 0.93159806 | O51: 0.87849253 | P51: 261630 | Q51: 0.058823529 | R51: 0 | S51: 0.85574972

Sheet PIVOT TABLE
A1: Vendor Performance Summary
A2: =INDEX(A4:A13,MATCH(MAX(B4:B13),B4:B13,0)) -> Vertex Solutions | B2: =MAX(B4:B13) -> 0.9787234 | G2: Defect Analysis
A3: Supplier Name | B3: Average of OTD | C3: Average of Quality Rate | D3: Average of Cost Score | E3: Average of Vendor Score | G3: Supplier Name | H3: Sum of Defect Qty | J3: Row Labels | K3: Average of Fill Rate | L3: Average of Quality Rate | M3: Sum of Order Value | N3: Average of Vendor Score | O3: Sum of OTD in Values
A4: Zenith Manufacturing | B4: 0.78571429 | C4: 0.92805106 | D4: 0.089797332 | E4: 0.79445124 | G4: Omega Industries | H4: 14695 | J4: Alpha Electronics | K4: 0.96161989 | L4: 0.98703947 | M4: 12712598 | N4: 0.87919471 | O4: 2
A5: Vertex Solutions | B5: 0.9787234 | C5: 0.98814566 | D5: 0.076840886 | E5: 0.88863759 | G5: Delta Supplies | H5: 12752 | J5: Beta Components | K5: 0.95644402 | L5: 0.96800494 | M5: 14904559 | N5: 0.83952263 | O5: 5
A6: Prime Circuits | B6: 0.85714286 | C6: 0.94802116 | D6: 0.12817136 | E6: 0.83200833 | G6: Gamma Technologies | H6: 9303 | J6: Delta Supplies | K6: 0.95959711 | L6: 0.90815694 | M6: 17650262 | N6: 0.83269458 | O6: 6
A7: Omega Industries | B7: 0.64583333 | C7: 0.87861385 | D7: 0.098883765 | E7: 0.72357997 | G7: Zenith Manufacturing | H7: 9102 | J7: Epsilon Systems | K7: 0.95918922 | L7: 0.97841745 | M7: 16584907 | N7: 0.87704248 | O7: 2 | P7: Category | Q7: Count
A8: Nexus Parts | B8: 0.92982456 | C8: 0.95726241 | D8: 0.066584593 | E8: 0.85802545 | G8: Nexus Parts | H8: 5462 | J8: Gamma Technologies | K8: 0.96208675 | L8: 0.93784885 | M8: 16822670 | N8: 0.8413742 | O8: 6 | P8: A | Q8: 6
A9: Gamma Technologies | B9: 0.89830508 | C9: 0.93784885 | D9: 0.082801659 | E9: 0.8413742 | G9: Prime Circuits | H9: 5246 | J9: Nexus Parts | K9: 0.96129224 | L9: 0.95726241 | M9: 17143945 | N9: 0.85802545 | O9: 4 | P9: B | Q9: 2
A10: Epsilon Systems | B10: 0.95918367 | C10: 0.97841745 | D10: 0.080059281 | E10: 0.87704248 | G10: Beta Components | H10: 3508 | J10: Omega Industries | K10: 0.95887052 | L10: 0.87861385 | M10: 13662668 | N10: 0.72357997 | O10: 17 | P10: C | Q10: 2
A11: Delta Supplies | B11: 0.89655172 | C11: 0.90815694 | D11: 0.097073878 | E11: 0.83269458 | G11: Epsilon Systems | H11: 2624 | J11: Prime Circuits | K11: 0.95963851 | L11: 0.94802116 | M11: 10735271 | N11: 0.83200833 | O11: 6
A12: Beta Components | B12: 0.88095238 | C12: 0.96800494 | D12: 0.054513852 | E12: 0.83952263 | G12: Vertex Solutions | H12: 1300 | J12: Vertex Solutions | K12: 0.96510221 | L12: 0.98814566 | M12: 17079564 | N12: 0.88863759 | O12: 1
A13: Alpha Electronics | B13: 0.95238095 | C13: 0.98703947 | D13: 0.098065089 | E13: 0.87919471 | G13: Alpha Electronics | H13: 1075 | J13: Zenith Manufacturing | K13: 0.96385234 | L13: 0.92805106 | M13: 15824235 | N13: 0.79445124 | O13: 12
A14: Grand Total | B14: 0.878 | C14: 0.94605704 | D14: 0.08682383 | E14: 0.8358749 | G14: Grand Total | H14: 65067 | J14: Grand Total | K14: 0.960877 | L14: 0.94605704 | M14: 153120679 | N14: 0.8358749 | O14: 61
A16: Monthly Spend | D16: Late Deliveries
A17: Month | B17: Sum of Order Value | D17: Supplier Name | E17: Sum of OTD in Values | G17: Supplier Name | H17: Sum of Order Value | J17: Row Labels | K17: Sum of Order Value | L17: Spend% | M17: Cumulative% | N17: ABC Analysis | O17: Count | P17: Category | Q17: Count | S17: Row Labels | T17: Sum of Order Value | U17: Cumulative%
A18: Jan | B18: 11666914 | D18: Omega Industries | E18: 17 | G18: Delta Supplies | H18: 17650262 | J18: Delta Supplies | K18: 17650262 | L18: =K18/SUM($K$18:$K$27) -> 0.11527027 | M18: =L18 -> 0.11527027 | N18: =IF(M18<=70%,"A",IF(M18<=90%,"B","C")) -> A | O18: =COUNTIF(N18:N27,"A") -> 6 | P18: A | Q18: =COUNTIF(P18:P27,"A") -> 1 | S18: Delta Supplies | T18: 17650262 | U18: 0.11527027
A19: Feb | B19: 11168085 | D19: Zenith Manufacturing | E19: 12 | G19: Nexus Parts | H19: 17143945 | J19: Nexus Parts | K19: 17143945 | L19: =K19/SUM($K$18:$K$27) -> 0.11196362 | M19: =L19+M18 -> 0.22723389 | N19: =IF(M19<=70%,"A",IF(M19<=90%,"B","C")) -> A | O19: =COUNTIF(N18:N27,"B") -> 2 | P19: B | Q19: =COUNTIF(P18:P27,"B") -> 1 | S19: Nexus Parts | T19: 17143945 | U19: 0.22723389
A20: Mar | B20: 10038762 | D20: Prime Circuits | E20: 6 | G20: Vertex Solutions | H20: 17079564 | J20: Vertex Solutions | K20: 17079564 | L20: =K20/SUM($K$18:$K$27) -> 0.11154316 | M20: =M19+L20 -> 0.33877704 | N20: =IF(M20<=70%,"A",IF(M20<=90%,"B","C")) -> A | O20: =COUNTIF(N18:N27,"C") -> 2 | P20: C | Q20: =COUNTIF(P18:P27,"C") -> 1 | S20: Vertex Solutions | T20: 17079564 | U20: 0.33877704
A21: Apr | B21: 11619046 | D21: Delta Supplies | E21: 6 | G21: Gamma Technologies | H21: 16822670 | J21: Gamma Technologies | K21: 16822670 | L21: =K21/SUM($K$18:$K$27) -> 0.10986543 | M21: =M20+L21 -> 0.44864248 | N21: =IF(M21<=70%,"A",IF(M21<=90%,"B","C")) -> A | S21: Gamma Technologies | T21: 16822670 | U21: 0.44864248
A22: May | B22: 14847313 | D22: Gamma Technologies | E22: 6 | G22: Epsilon Systems | H22: 16584907 | J22: Epsilon Systems | K22: 16584907 | L22: =K22/SUM($K$18:$K$27) -> 0.10831265 | M22: =M21+L22 -> 0.55695513 | N22: =IF(M22<=70%,"A",IF(M22<=90%,"B","C")) -> A | S22: Epsilon Systems | T22: 16584907 | U22: 0.55695513
A23: Jun | B23: 15825998 | D23: Beta Components | E23: 5 | G23: Zenith Manufacturing | H23: 15824235 | J23: Zenith Manufacturing | K23: 15824235 | L23: =K23/SUM($K$18:$K$27) -> 0.10334486 | M23: =M22+L23 -> 0.66029999 | N23: =IF(M23<=70%,"A",IF(M23<=90%,"B","C")) -> A | S23: Zenith Manufacturing | T23: 15824235 | U23: 0.66029999
A24: Jul | B24: 15148841 | D24: Nexus Parts | E24: 4 | G24: Beta Components | H24: 14904559 | J24: Beta Components | K24: 14904559 | L24: =K24/SUM($K$18:$K$27) -> 0.097338642 | M24: =M23+L24 -> 0.75763863 | N24: =IF(M24<=70%,"A",IF(M24<=90%,"B","C")) -> B | S24: Beta Components | T24: 14904559 | U24: 0.75763863
A25: Aug | B25: 10197668 | D25: Alpha Electronics | E25: 2 | G25: Omega Industries | H25: 13662668 | J25: Omega Industries | K25: 13662668 | L25: =K25/SUM($K$18:$K$27) -> 0.089228105 | M25: =M24+L25 -> 0.84686674 | N25: =IF(M25<=70%,"A",IF(M25<=90%,"B","C")) -> B | S25: Omega Industries | T25: 13662668 | U25: 0.84686674
A26: Sep | B26: 10809151 | D26: Epsilon Systems | E26: 2 | G26: Alpha Electronics | H26: 12712598 | J26: Alpha Electronics | K26: 12712598 | L26: =K26/SUM($K$18:$K$27) -> 0.083023391 | M26: =M25+L26 -> 0.92989013 | N26: =IF(M26<=70%,"A",IF(M26<=90%,"B","C")) -> C | S26: Alpha Electronics | T26: 12712598 | U26: 0.92989013
A27: Oct | B27: 16605357 | D27: Vertex Solutions | E27: 1 | G27: Prime Circuits | H27: 10735271 | J27: Prime Circuits | K27: 10735271 | L27: =K27/SUM($K$18:$K$27) -> 0.070109871 | M27: =M26+L27 -> 1 | N27: =IF(M27<=70%,"A",IF(M27<=90%,"B","C")) -> C | S27: Prime Circuits | T27: 10735271 | U27: 1
A28: Nov | B28: 8736628 | D28: Grand Total | E28: 61 | G28: Grand Total | H28: 153120679 | J28: Grand Total | K28: 153120679 | L28: =K28/SUM($K$18:$K$27) -> 1 | S28: Grand Total | T28: 153120679
A29: Dec | B29: 16456916
A30: Grand Total | B30: 153120679
G31: Supplier Vs Vendor Score%
D32: Supplier Name | E32: Sum of Order Value | G32: Supplier Name | H32: Average of Vendor Score
A33: Row Labels | B33: Average of OTD | D33: Delta Supplies | E33: 17650262 | G33: Vertex Solutions | H33: 0.88863759
A34: Vertex Solutions | B34: 0.9787234 | D34: Nexus Parts | E34: 17143945 | G34: Alpha Electronics | H34: 0.87919471
A35: Epsilon Systems | B35: 0.95918367 | D35: Vertex Solutions | E35: 17079564 | G35: Epsilon Systems | H35: 0.87704248
A36: Alpha Electronics | B36: 0.95238095 | D36: Gamma Technologies | E36: 16822670 | G36: Nexus Parts | H36: 0.85802545
A37: Nexus Parts | B37: 0.92982456 | D37: Epsilon Systems | E37: 16584907 | G37: Gamma Technologies | H37: 0.8413742
A38: Gamma Technologies | B38: 0.89830508 | D38: Zenith Manufacturing | E38: 15824235 | G38: Beta Components | H38: 0.83952263
A39: Delta Supplies | B39: 0.89655172 | D39: Beta Components | E39: 14904559 | G39: Delta Supplies | H39: 0.83269458
A40: Beta Components | B40: 0.88095238 | D40: Omega Industries | E40: 13662668 | G40: Prime Circuits | H40: 0.83200833
A41: Prime Circuits | B41: 0.85714286 | D41: Alpha Electronics | E41: 12712598 | G41: Zenith Manufacturing | H41: 0.79445124
...

Sheet AVP DASHBOARD
J1: ADVANCED VENDOR PERFORMANCE DASHBOARD
J2: Supplier Performance| Spend Analysis|Risk Management
A4: TOTAL VENDOR | E4: TOTAL SPEND | I4: AVERAGE OTD | M4: BEST VENDOR | P4: BEST OTD
A6: =COUNTA('PIVOT TABLE'!A5:A14) -> 10 | E6: =SUM('PIVOT TABLE'!E33:E42) -> 153120679 | I6: =AVERAGE('PIVOT TABLE'!B34:B43) -> 0.87846123 | M6: =INDEX('PIVOT TABLE'!A4:A13,MATCH(MAX('PIVOT TABLE'!B4:B13),'PIVOT TABLE'!B4:B13,0)) -> Vertex Solutions | P6: =MAX('PIVOT TABLE'!B4:B13,'PIVOT TABLE'!B4:B13,0) -> 0.9787234
M8: Vendor Performance Scorecard
M9: Vendor Name | N9: ='PIVOT TABLE'!J4 -> Alpha Electronics
M10: Spend | N10: ='PIVOT TABLE'!M4 -> 12712598
M11: OTD | N11: ='PIVOT TABLE'!O4 -> 2
M12: Quality Rate | N12: ='PIVOT TABLE'!L4 -> 0.98703947
M13: Fill Rate | N13: ='PIVOT TABLE'!K4 -> 0.96161989
M14: Vendor Score | N14: ='PIVOT TABLE'!N4 -> 0.87919471

Sheet DASHBOARD
B2: 📊Total Vendor | E2: 📦TOTAL SPEND | I2: 🏆BEST VENDOR | M2: 🚚BEST OTD | Q2: 🚚AVERAGE OTD
B6: =COUNTA('PIVOT TABLE'!A4:A13) -> 10 | E6: =SUM('PIVOT TABLE'!B18:B29) -> 153120679 | I6: ='PIVOT TABLE'!A2 -> Vertex Solutions | M6: ='PIVOT TABLE'!B2 -> 0.9787234 | Q6: =AVERAGE('PIVOT TABLE'!B4:B13) -> 0.87846123

Sheet Sheet1

Sheet SOURCE DATA
A1: PO Number | B1: Vendor ID | C1: Vendor Name | D1: Category | E1: Month | F1: Order Qty | G1: Received Qty | H1: Planned Date | I1: Actual Receipt Date | J1: Defect Qty | K1: Unit Price | L1: Delivery Delay | M1: OTD | N1: Fill Rate | O1: Quality Rate | P1: Order Value | Q1: Cost Score | R1: OTD in Values | S1: Vendor Score | T1: Column1 | U1: Status | V1: satt
A2: PO1457 | B2: V010 | C2: Vertex Solutions | D2: IC | E2: Dec | F2: 750 | G2: 711 | H2: 46380 | I2: 46378 | J2: 13 | K2: 6 | L2: =I2-H2 -> -2 | M2: =IF(L2<=0,1,0) -> 1 | N2: =G2/F2 -> 0.948 | O2: =(G2-J2)/G2 -> 0.98171589 | P2: =G2*K2 -> 4266 | Q2: =MIN(Table1[Unit Price])/Table1[[#This Row],[Unit Price]] -> 0.83333333 | R2: =IF(Table1[[#This Row],[Delivery Delay]]>0,1,0) -> 0 | S2: =(Table1[[#This Row],[OTD]]*0.4)+(Table1[[#This Row],[Quality Rate]]*0.3)+(Table1[[#This Row],[Fill Rate]]*0.2)+(Table1[[#This Row],[Cost Score]]*0.1) -> 0.9674481 | T2: =MAX(Table1[OTD]) -> 1 | U2: =IF(Table1[[#This Row],[Vendor Score]]>=90%,"Excellent",IF(Table1[[#This Row],[Vendor Score]]>=75%,"Moderate","Poor")) -> Excellent
A3: PO1476 | B3: V004 | C3: Delta Supplies | D3: Capacitor | E3: Jul | F3: 389 | G3: 382 | H3: 46215 | I3: 46215 | J3: 38 | K3: 5 | L3: =I3-H3 -> 0 | M3: =IF(L3<=0,1,0) -> 1 | N3: =G3/F3 -> 0.98200514 | O3: =(G3-J3)/G3 -> 0.90052356 | P3: =G3*K3 -> 1910 | Q3: =MIN(Table1[Unit Price])/Table1[[#This Row],[Unit Price]] -> 1 | R3: =IF(Table1[[#This Row],[Delivery Delay]]>0,1,0) -> 0 | S3: =(Table1[[#This Row],[OTD]]*0.4)+(Table1[[#This Row],[Quality Rate]]*0.3)+(Table1[[#This Row],[Fill Rate]]*0.2)+(Table1[[#This Row],[Cost Score]]*0.1) -> 0.9665581 | T3: =MAX(Table1[OTD]) -> 1 | U3: =IF(Table1[[#This Row],[Vendor Score]]>=90%,"Excellent",IF(Table1[[#This Row],[Vendor Score]]>=75%,"Moderate","Poor")) -> Excellent
A4: PO1238 | B4: V001 | C4: Alpha Electronics | D4: Capacitor | E4: May | F4: 3055 | G4: 2979 | H4: 46162 | I4: 46161 | J4: 35 | K4: 7 | L4: =I4-H4 -> -1 | M4: =IF(L4<=0,1,0) -> 1 | N4: =G4/F4 -> 0.97512275 | O4: =(G4-J4)/G4 -> 0.98825109 | P4: =G4*K4 -> 20853 | Q4: =MIN(Table1[Unit Price])/Table1[[#This Row],[Unit Price]] -> 0.71428571 | R4: =IF(Table1[[#This Row],[Delivery Delay]]>0,1,0) -> 0 | S4: =(Table1[[#This Row],[OTD]]*0.4)+(Table1[[#This Row],[Quality Rate]]*0.3)+(Table1[[#This Row],[Fill Rate]]*0.2)+(Table1[[#This Row],[Cost Score]]*0.1) -> 0.96292845 | T4: =MAX(Table1[OTD]) -> 1 | U4: =IF(Table1[[#This Row],[Vendor Score]]>=90%,"Excellent",IF(Table1[[#This Row],[Vendor Score]]>=75%,"Moderate","Poor")) -> Excellent
A5: PO1196 | B5: V005 | C5: Epsilon Systems | D5: Connector | E5: Jan | F5: 1614 | G5: 1546 | H5: 46032 | I5: 46031 | J5: 31 | K5: 7 | L5: =I5-H5 -> -1 | M5: =IF(L5<=0,1,0) -> 1 | N5: =G5/F5 -> 0.95786865 | O5: =(G5-J5)/G5 -> 0.97994825 | P5: =G5*K5 -> 10822 | Q5: =MIN(Table1[Unit Price])/Table1[[#This Row],[Unit Price]] -> 0.71428571 | R5: =IF(Table1[[#This Row],[Delivery Delay]]>0,1,0) -> 0 | S5: =(Table1[[#This Row],[OTD]]*0.4)+(Table1[[#This Row],[Quality Rate]]*0.3)+(Table1[[#This Row],[Fill Rate]]*0.2)+(Table1[[#This Row],[Cost Score]]*0.1) -> 0.95698678 | T5: =MAX(Table1[OTD]) -> 1 | U5: =IF(Table1[[#This Row],[Vendor Score]]>=90%,"Excellent",IF(Table1[[#This Row],[Vendor Score]]>=75%,"Moderate","Poor")) -> Excellent
A6: PO1208 | B6: V008 | C6: Prime Circuits | D6: Capacitor | E6: Dec | F6: 2083 | G6: 1935 | H6: 46363 | I6: 46363 | J6: 97 | K6: 6 | L6: =I6-H6 -> 0 | M6: =IF(L6<=0,1,0) -> 1 | N6: =G6/F6 -> 0.92894863 | O6: =(G6-J6)/G6 -> 0.9498708 | P6: =G6*K6 -> 11610 | Q6: =MIN(Table1[Unit Price])/Table1[[#This Row],[Unit Price]] -> 0.83333333 | R6: =IF(Table1[[#This Row],[Delivery Delay]]>0,1,0) -> 0 | S6: =(Table1[[#This Row],[OTD]]*0.4)+(Table1[[#This Row],[Quality Rate]]*0.3)+(Table1[[#This Row],[Fill Rate]]*0.2)+(Table1[[#This Row],[Cost Score]]*0.1) -> 0.9540843 | T6: =MAX(Table1[OTD]) -> 1 | U6: =IF(Table1[[#This Row],[Vendor Score]]>=90%,"Excellent",IF(Table1[[#This Row],[Vendor Score]]>=75%,"Moderate","Poor")) -> Excellent
A7: PO1311 | B7: V008 | C7: Prime Circuits | D7: PCB | E7: Jul | F7: 4105 | G7: 3781 | H7: 46234 | I7: 46233 | J7: 192 | K7: 6 | L7: =I7-H7 -> -1 | M7: =IF(L7<=0,1,0) -> 1 | N7: =G7/F7 -> 0.92107186 | O7: =(G7-J7)/G7 -> 0.94921978 | P7: =G7*K7 -> 22686 | Q7: =MIN(Table1[Unit Price])/Table1[[#This Row],[Unit Price]] -> 0.83333333 | R7: =IF(Table1[[#This Row],[Delivery Delay]]>0,1,0) -> 0 | S7: =(Table1[[#This Row],[OTD]]*0.4)+(Table1[[#This Row],[Quality Rate]]*0.3)+(Table1[[#This Row],[Fill Rate]]*0.2)+(Table1[[#This Row],[Cost Score]]*0.1) -> 0.95231364 | T7: =MAX(Table1[OTD]) -> 1 | U7: =IF(Table1[[#This Row],[Vendor Score]]>=90%,"Excellent",IF(Table1[[#This Row],[Vendor Score]]>=75%,"Moderate","Poor")) -> Excellent
A8: PO1261 | B8: V001 | C8: Alpha Electronics | D8: PCB | E8: May | F8: 1084 | G8: 1070 | H8: 46148 | I8: 46148 | J8: 16 | K8: 9 | L8: =I8-H8 -> 0 | M8: =IF(L8<=0,1,0) -> 1 | N8: =G8/F8 -> 0.98708487 | O8: =(G8-J8)/G8 -> 0.98504673 | P8: =G8*K8 -> 9630 | Q8: =MIN(Table1[Unit Price])/Table1[[#This Row],[Unit Price]] -> 0.55555556 | R8: =IF(Table1[[#This Row],[Delivery Delay]]>0,1,0) -> 0 | S8: =(Table1[[#This Row],[OTD]]*0.4)+(Table1[[#This Row],[Quality Rate]]*0.3)+(Table1[[#This Row],[Fill Rate]]*0.2)+(Table1[[#This Row],[Cost Score]]*0.1) -> 0.94848655 | T8: =MAX(Table1[OTD]) -> 1 | U8: =IF(Table1[[#This Row],[Vendor Score]]>=90%,"Excellent",IF(Table1[[#This Row],[Vendor Score]]>=75%,"Moderate","Poor")) -> Excellent
A9: PO1242 | B9: V004 | C9: Delta Supplies | D9: Connector | E9: Jul | F9: 3752 | G9: 3559 | H9: 46217 | I9: 46217 | J9: 322 | K9: 6 | L9: =I9-H9 -> 0 | M9: =IF(L9<=0,1,0) -> 1 | N9: =G9/F9 -> 0.94856077 | O9: =(G9-J9)/G9 -> 0.90952515 | P9: =G9*K9 -> 21354 | Q9: =MIN(Table1[Unit Price])/Table1[[#This Row],[Unit Price]] -> 0.83333333 | R9: =IF(Table1[[#This Row],[Delivery Delay]]>0,1,0) -> 0 | S9: =(Table1[[#This Row],[OTD]]*0.4)+(Table1[[#This Row],[Quality Rate]]*0.3)+(Table1[[#This Row],[Fill Rate]]*0.2)+(Table1[[#This Row],[Cost Score]]*0.1) -> 0.94590303 | T9: =MAX(Table1[OTD]) -> 1 | U9: =IF(Table1[[#This Row],[Vendor Score]]>=90%,"Excellent",IF(Table1[[#This Row],[Vendor Score]]>=75%,"Moderate","Poor")) -> Excellent
A10: PO1253 | B10: V010 | C10: Vertex Solutions | D10: Connector | E10: Jan | F10: 1429 | G10: 1374 | H10: 46027 | I10: 46026 | J10: 18 | K10: 9 | L10: =I10-H10 -> -1 | M10: =IF(L10<=0,1,0) -> 1 | N10: =G10/F10 -> 0.96151155 | O10: =(G10-J10)/G10 -> 0.98689956 | P10: =G10*K10 -> 12366 | Q10: =MIN(Table1[Unit Price])/Table1[[#This Row],[Unit Price]] -> 0.55555556 | R10: =IF(Table1[[#This Row],[Delivery Delay]]>0,1,0) -> 0 | S10: =(Table1[[#This Row],[OTD]]*0.4)+(Table1[[#This Row],[Quality Rate]]*0.3)+(Table1[[#This Row],[Fill Rate]]*0.2)+(Table1[[#This Row],[Cost Score]]*0.1) -> 0.94392773 | T10: =MAX(Table1[OTD]) -> 1 | U10: =IF(Table1[[#This Row],[Vendor Score]]>=90%,"Excellent",IF(Table1[[#This Row],[Vendor Score]]>=75%,"Moderate","Poor")) -> Excellent
A11: PO1314 | B11: V001 | C11: Alpha Electronics | D11: Connector | E11: May | F11: 1048 | G11: 1030 | H11: 46162 | I11: 46162 | J11: 11 | K11: 10 | L11: =I11-H11 -> 0 | M11: =IF(L11<=0,1,0) -> 1 | N11: =G11/F11 -> 0.98282443 | O11: =(G11-J11)/G11 -> 0.98932039 | P11: =G11*K11 -> 10300 | Q11: =MIN(Table1[Unit Price])/Table1[[#This Row],[Unit Price]] -> 0.5 | R11: =IF(Table1[[#This Row],[Delivery Delay]]>0,1,0) -> 0 | S11: =(Table1[[#This Row],[OTD]]*0.4)+(Table1[[#This Row],[Quality Rate]]*0.3)+(Table1[[#This Row],[Fill Rate]]*0.2)+(Table1[[#This Row],[Cost Score]]*0.1) -> 0.943361 | T11: =MAX(Table1[OTD]) -> 1 | U11: =IF(Table1[[#This Row],[Vendor Score]]>=90%,"Excellent",IF(Table1[[#This Row],[Vendor Score]]>=75%,"Moderate","Poor")) -> Excellent
A12: PO1266 | B12: V007 | C12: Nexus Parts | D12: IC | E12: Dec | F12: 3636 | G12: 3424 | H12: 46358 | I12: 46357 | J12: 137 | K12: 8 | L12: =I12-H12 -> -1 | M12: =IF(L12<=0,1,0) -> 1 | N12: =G12/F12 -> 0.94169417 | O12: =(G12-J12)/G12 -> 0.95998832 | P12: =G12*K12 -> 27392 | Q12: =MIN(Table1[Unit Price])/Table1[[#This Row],[Unit Price]] -> 0.625 | R12: =IF(Table1[[#This Row],[Delivery Delay]]>0,1,0) -> 0 | S12: =(Table1[[#This Row],[OTD]]*0.4)+(Table1[[#This Row],[Quality Rate]]*0.3)+(Table1[[#This Row],[Fill Rate]]*0.2)+(Table1[[#This Row],[Cost Score]]*0.1) -> 0.93883533 | T12: =MAX(Table1[OTD]) -> 1 | U12: =IF(Table1[[#This Row],[Vendor Score]]>=90%,"Excellent",IF(Table1[[#This Row],[Vendor Score]]>=75%,"Moderate","Poor")) -> Excellent
A13: PO1220 | B13: V008 | C13: Prime Circuits | D13: IC | E13: Jan | F13: 4317 | G13: 4089 | H13: 46037 | I13: 46037 | J13: 207 | K13: 9 | L13: =I13-H13 -> 0 | M13: =IF(L13<=0,1,0) -> 1 | N13: =G13/F13 -> 0.94718555 | O13: =(G13-J13)/G13 -> 0.94937638 | P13: =G13*K13 -> 36801 | Q13: =MIN(Table1[Unit Price])/Table1[[#This Row],[Unit Price]] -> 0.55555556 | R13: =IF(Table1[[#This Row],[Delivery Delay]]>0,1,0) -> 0 | S13: =(Table1[[#This Row],[OTD]]*0.4)+(Table1[[#This Row],[Quality Rate]]*0.3)+(Table1[[#This Row],[Fill Rate]]*0.2)+(Table1[[#This Row],[Cost Score]]*0.1) -> 0.92980558 | T13: =MAX(Table1[OTD]) -> 1 | U13: =IF(Table1[[#This Row],[Vendor Score]]>=90%,"Excellent",IF(Table1[[#This Row],[Vendor Score]]>=75%,"Moderate","Poor")) -> Excellent
... A501: PO1463 | B501: V006 | C501: Omega Industries | D501: Capacitor | E501: Jan | F501: 2032 | G501: 1873 | H501: 46035 | I501: 46036 | J501: 226 | K501: 141 | L501: =I501-H501 -> 1 | M501: =IF(L501<=0,1,0) -> 0 | N501: =G501/F501 -> 0.92175197 | O501: =(G501-J501)/G501 -> 0.87933796 | P501: =G501*K501 -> 264093 | Q501: =MIN(Table1[Unit Price])/Table1[[#This Row],[Unit Price]] -> 0.035460993 | R501: =IF(Table1[[#This Row],[Delivery Delay]]>0,1,0) -> 1 | S501: =(Table1[[#This Row],[OTD]]*0.4)+(Table1[[#This Row],[Quality Rate]]*0.3)+(Table1[[#This Row],[Fill Rate]]*0.2)+(Table1[[#This Row],[Cost Score]]*0.1) -> 0.45169788 | T501: =MAX(Table1[OTD]) -> 1 | U501: =IF(Table1[[#This Row],[Vendor Score]]>=90%,"Excellent",IF(Table1[[#This Row],[Vendor Score]]>=75%,"Moderate","Poor")) -> Poor

Sheet Sheet4
B2: Supplier Name | C2: Average of OTD | D2: Average of Quality Rate | E2: Average of Cost Score | F2: Average of Vendor Score | H2: Supplier Name | I2: Sum of Defect Qty
B3: Vertex Solutions | C3: 0.9787234 | D3: 0.98814566 | E3: 0.076840886 | F3: 0.88863759 | H3: Omega Industries | I3: 14695
B4: Epsilon Systems | C4: 0.95918367 | D4: 0.97841745 | E4: 0.080059281 | F4: 0.87704248 | H4: Delta Supplies | I4: 12752
B5: Alpha Electronics | C5: 0.95238095 | D5: 0.98703947 | E5: 0.098065089 | F5: 0.87919471 | H5: Gamma Technologies | I5: 9303
B6: Nexus Parts | C6: 0.92982456 | D6: 0.95726241 | E6: 0.066584593 | F6: 0.85802545 | H6: Zenith Manufacturing | I6: 9102
B7: Gamma Technologies | C7: 0.89830508 | D7: 0.93784885 | E7: 0.082801659 | F7: 0.8413742 | H7: Nexus Parts | I7: 5462
B8: Delta Supplies | C8: 0.89655172 | D8: 0.90815694 | E8: 0.097073878 | F8: 0.83269458 | H8: Prime Circuits | I8: 5246
B9: Beta Components | C9: 0.88095238 | D9: 0.96800494 | E9: 0.054513852 | F9: 0.83952263 | H9: Beta Components | I9: 3508
B10: Prime Circuits | C10: 0.85714286 | D10: 0.94802116 | E10: 0.12817136 | F10: 0.83200833 | H10: Epsilon Systems | I10: 2624
B11: Zenith Manufacturing | C11: 0.78571429 | D11: 0.92805106 | E11: 0.089797332 | F11: 0.79445124 | H11: Vertex Solutions | I11: 1300
B12: Omega Industries | C12: 0.64583333 | D12: 0.87861385 | E12: 0.098883765 | F12: 0.72357997 | H12: Alpha Electronics | I12: 1075
B13: Grand Total | C13: 0.878 | D13: 0.94605704 | E13: 0.08682383 | F13: 0.8358749 | H13: Grand Total | I13: 65067
B15: Monthly Spend | E15: Late Deliveries
B16: Month | C16: Sum of Order Value | E16: Supplier Name | F16: Sum of OTD in Values | H16: Supplier Name | I16: Sum of Order Value
B17: Jan | C17: 11666914 | E17: Omega Industries | F17: 17 | H17: Delta Supplies | I17: 17650262
B18: Feb | C18: 11168085 | E18: Zenith Manufacturing | F18: 12 | H18: Nexus Parts | I18: 17143945
B19: Mar | C19: 10038762 | E19: Prime Circuits | F19: 6 | H19: Vertex Solutions | I19: 17079564
B20: Apr | C20: 11619046 | E20: Delta Supplies | F20: 6 | H20: Gamma Technologies | I20: 16822670
B21: May | C21: 14847313 | E21: Gamma Technologies | F21: 6 | H21: Epsilon Systems | I21: 16584907
B22: Jun | C22: 15825998 | E22: Beta Components | F22: 5 | H22: Zenith Manufacturing | I22: 15824235
B23: Jul | C23: 15148841 | E23: Nexus Parts | F23: 4 | H23: Beta Components | I23: 14904559
B24: Aug | C24: 10197668 | E24: Alpha Electronics | F24: 2 | H24: Omega Industries | I24: 13662668
B25: Sep | C25: 10809151 | E25: Epsilon Systems | F25: 2 | H25: Alpha Electronics | I25: 12712598
B26: Oct | C26: 16605357 | E26: Vertex Solutions | F26: 1 | H26: Prime Circuits | I26: 10735271
B27: Nov | C27: 8736628 | E27: Grand Total | F27: 61 | H27: Grand Total | I27: 153120679
B28: Dec | C28: 16456916
B29: Grand Total | C29: 153120679
